Workbook
Name UPDATE: 'Data Sheet'!$E$1

Sheet Financials>
B2: ="Historical Financial Statement - "&UPDATE -> Historical Financial Statement - Tata Motors
B3: Years | C3: ='Data Sheet'!B16 -> 42460 | D3: ='Data Sheet'!C16 -> 42825 | E3: ='Data Sheet'!D16 -> 43190 | F3: ='Data Sheet'!E16 -> 43555 | G3: ='Data Sheet'!F16 -> 43921 | H3: ='Data Sheet'!G16 -> 44286 | I3: ='Data Sheet'!H16 -> 44651 | J3: ='Data Sheet'!I16 -> 45016 | ... L3: ='Data Sheet'!K16 -> 45747 | M3: LTM
A5: x | B5: Income Statement
B7: Sales | C7: =IFERROR('Data Sheet'!B17,0) -> 273045.6 | D7: =IFERROR('Data Sheet'!C17,0) -> 269692.51 | E7: =IFERROR('Data Sheet'!D17,0) -> 291550.48 | F7: =IFERROR('Data Sheet'!E17,0) -> 301938.4 | G7: =IFERROR('Data Sheet'!F17,0) -> 261067.97 | H7: =IFERROR('Data Sheet'!G17,0) -> 249794.75 | I7: =IFERROR('Data Sheet'!H17,0) -> 278453.62 | J7: =IFERROR('Data Sheet'!I17,0) -> 345966.97 | ... L7: =IFERROR('Data Sheet'!K17,0) -> 439695 | M7: =IFERROR(SUM('Data Sheet'!H42:K42),0) -> 437968
B8: Sales Growth | C8: =IFERROR(C7/B7-1, "-") -> - | D8: =IFERROR(D7/C7-1, 0) -> -0.01228033 | E8: =IFERROR(E7/D7-1, 0) -> 0.081047746 | F8: =IFERROR(F7/E7-1, 0) -> 0.035629919 | G8: =IFERROR(G7/F7-1, 0) -> -0.13536016 | H8: =IFERROR(H7/G7-1, 0) -> -0.043181168 | I8: =IFERROR(I7/H7-1, 0) -> 0.11472967 | J8: =IFERROR(J7/I7-1, 0) -> 0.24245815 | K8: =IFERROR(K7/J7-1, 0) -> 0.25450126 | ... M8: =IFERROR(M7/L7-1, 0) -> -0.0039277226
B10: COGS | C10: =IFERROR(SUM('Data Sheet'!B18,'Data Sheet'!B20,'Data Sheet'!B21) - 1 *'Data Sheet'!B19, 0) -> 176628.18 | D10: =IFERROR(SUM('Data Sheet'!C18,'Data Sheet'!C20,'Data Sheet'!C21) - 1 *'Data Sheet'!C19, 0) -> 177121.35 | E10: =IFERROR(SUM('Data Sheet'!D18,'Data Sheet'!D20,'Data Sheet'!D21) - 1 *'Data Sheet'!D19, 0) -> 198129.74 | F10: =IFERROR(SUM('Data Sheet'!E18,'Data Sheet'!E20,'Data Sheet'!E21) - 1 *'Data Sheet'!E19, 0) -> 209601.66 | G10: =IFERROR(SUM('Data Sheet'!F18,'Data Sheet'!F20,'Data Sheet'!F21) - 1 *'Data Sheet'!F19, 0) -> 179937.47 | H10: =IFERROR(SUM('Data Sheet'!G18,'Data Sheet'!G20,'Data Sheet'!G21) - 1 *'Data Sheet'!G19, 0) -> 167677.56 | I10: =IFERROR(SUM('Data Sheet'!H18,'Data Sheet'!H20,'Data Sheet'!H21) - 1 *'Data Sheet'!H19, 0) -> 192491.49 | J10: =IFERROR(SUM('Data Sheet'!I18,'Data Sheet'!I20,'Data Sheet'!I21) - 1 *'Data Sheet'!I19, 0) -> 240748.94 | ... L10: =IFERROR(SUM('Data Sheet'!K18,'Data Sheet'!K20,'Data Sheet'!K21) - 1 *'Data Sheet'!K19, 0) -> 293042 | M10: =IFERROR(SUM('Data Sheet'!H43:K43),0) -> 386344
B11: COGS as % of Sales | C11: =IFERROR(C10/C7, 0) -> 0.64688162 | D11: =IFERROR(D10/D7, 0) -> 0.65675294 | E11: =IFERROR(E10/E7, 0) -> 0.67957268 | F11: =IFERROR(F10/F7, 0) -> 0.69418683 | G11: =IFERROR(G10/G7, 0) -> 0.6892361 | H11: =IFERROR(H10/H7, 0) -> 0.67126135 | I11: =IFERROR(I10/I7, 0) -> 0.69128744 | J11: =IFERROR(J10/J7, 0) -> 0.69587261 | ... M11: =IFERROR(M10/M7, 0) -> 0.88212837
B13: Gross Profit | C13: =IFERROR(C7-C10, 0) -> 96417.42 | D13: =IFERROR(D7-D10, 0) -> 92571.16 | E13: =IFERROR(E7-E10, 0) -> 93420.74 | F13: =IFERROR(F7-F10, 0) -> 92336.74 | G13: =IFERROR(G7-G10, 0) -> 81130.5 | H13: =IFERROR(H7-H10, 0) -> 82117.19 | I13: =IFERROR(I7-I10, 0) -> 85962.13 | J13: =IFERROR(J7-J10, 0) -> 105218.03 | ... M13: =IFERROR(M7-M10, 0) -> 51624
B14: Gross Margin | C14: =C13/C7 -> 0.35311838 | D14: =D13/D7 -> 0.34324706 | E14: =E13/E7 -> 0.32042732 | F14: =F13/F7 -> 0.30581317 | G14: =G13/G7 -> 0.3107639 | H14: =H13/H7 -> 0.32873865 | I14: =I13/I7 -> 0.30871256 | J14: =J13/J7 -> 0.30412739 | ... M14: =M13/M7 -> 0.11787163
B16: Selling & General Expenses | C16: =IFERROR(SUM('Data Sheet'!B23:B24),0) -> 29141.28 | D16: =IFERROR(SUM('Data Sheet'!C23:C24),0) -> 34649.58 | E16: =IFERROR(SUM('Data Sheet'!D23:D24),0) -> 31662.97 | F16: =IFERROR(SUM('Data Sheet'!E23:E24),0) -> 34428.54 | G16: =IFERROR(SUM('Data Sheet'!F23:F24),0) -> 32704.83 | H16: =IFERROR(SUM('Data Sheet'!G23:G24),0) -> 22181.28 | I16: =IFERROR(SUM('Data Sheet'!H23:H24),0) -> 30433.52 | J16: =IFERROR(SUM('Data Sheet'!I23:I24),0) -> 39747.53 | ... M16: =IFERROR(SUM('Data Sheet'!L23:L24),0) -> 0
B17: Selling Exp % | C17: =IFERROR(C16/C7, 0) -> 0.10672679 | D17: =IFERROR(D16/D7, 0) -> 0.1284781 | E17: =IFERROR(E16/E7, 0) -> 0.10860202 | F17: =IFERROR(F16/F7, 0) -> 0.11402505 | G17: =IFERROR(G16/G7, 0) -> 0.12527324 | H17: =IFERROR(H16/H7, 0) -> 0.088798023 | I17: =IFERROR(I16/I7, 0) -> 0.10929475 | J17: =IFERROR(J16/J7, 0) -> 0.11488822 | ... M17: =IFERROR(M16/M7, 0) -> 0
B19: EBITDA | C19: =IFERROR(C13-C16,0) -> 67276.14 | D19: =IFERROR(D13-D16,0) -> 57921.58 | E19: =IFERROR(E13-E16,0) -> 61757.77 | F19: =IFERROR(F13-F16,0) -> 57908.2 | G19: =IFERROR(G13-G16,0) -> 48425.67 | H19: =IFERROR(H13-H16,0) -> 59935.91 | I19: =IFERROR(I13-I16,0) -> 55528.61 | J19: =IFERROR(J13-J16,0) -> 65470.5 | ... M19: =IFERROR(M13-M16,0) -> 51624
B20: EBITDA Margins | C20: =C19/C7 -> 0.24639159 | D20: =D19/D7 -> 0.21476896 | E20: =E19/E7 -> 0.21182531 | F20: =F19/F7 -> 0.19178813 | G20: =G19/G7 -> 0.18549066 | H20: =H19/H7 -> 0.23994063 | I20: =I19/I7 -> 0.19941781 | J20: =J19/J7 -> 0.18923916 | ... M20: =M19/M7 -> 0.11787163
B22: Interest | C22: =IFERROR('Data Sheet'!B27,0) -> 4889.08 | D22: =IFERROR('Data Sheet'!C27,0) -> 4238.01 | E22: =IFERROR('Data Sheet'!D27,0) -> 4681.79 | F22: =IFERROR('Data Sheet'!E27,0) -> 5758.6 | G22: =IFERROR('Data Sheet'!F27,0) -> 7243.33 | H22: =IFERROR('Data Sheet'!G27,0) -> 8097.17 | I22: =IFERROR('Data Sheet'!H27,0) -> 9311.86 | J22: =IFERROR('Data Sheet'!I27,0) -> 10225.48 | ... L22: =IFERROR('Data Sheet'!K27,0) -> 5083 | M22: =IFERROR(SUM('Data Sheet'!H46:K46),0) -> 5167
B23: Interest as a % of Sales | C23: =IFERROR(C22/C7,0) -> 0.017905727 | D23: =IFERROR(D22/D7,0) -> 0.01571423 | E23: =IFERROR(E22/E7,0) -> 0.016058248 | F23: =IFERROR(F22/F7,0) -> 0.019072102 | G23: =IFERROR(G22/G7,0) -> 0.027744997 | H23: =IFERROR(H22/H7,0) -> 0.032415293 | I23: =IFERROR(I22/I7,0) -> 0.033441332 | J23: =IFERROR(J22/J7,0) -> 0.029556232 | ... M23: =IFERROR(M22/M7,0) -> 0.011797666
B25: Depriciation | C25: ='Data Sheet'!B26 -> 16710.78 | D25: ='Data Sheet'!C26 -> 17904.99 | E25: ='Data Sheet'!D26 -> 21553.59 | F25: ='Data Sheet'!E26 -> 23590.63 | G25: ='Data Sheet'!F26 -> 21425.43 | H25: ='Data Sheet'!G26 -> 23546.71 | I25: ='Data Sheet'!H26 -> 24835.69 | J25: ='Data Sheet'!I26 -> 24860.36 | ... L25: ='Data Sheet'!K26 -> 23256 | M25: =IFERROR(SUM('Data Sheet'!H45:K45),0) -> 22019
B26: Depriciation as a % of Sales | C26: =IFERROR(C25/C7,0) -> 0.061201426 | D26: =IFERROR(D25/D7,0) -> 0.066390387 | E26: =IFERROR(E25/E7,0) -> 0.073927472 | F26: =IFERROR(F25/F7,0) -> 0.078130605 | G26: =IFERROR(G25/G7,0) -> 0.082068398 | H26: =IFERROR(H25/H7,0) -> 0.094264231 | I26: =IFERROR(I25/I7,0) -> 0.089191478 | J26: =IFERROR(J25/J7,0) -> 0.071857611 | ... M26: =IFERROR(M25/M7,0) -> 0.050275363
B28: EBT | C28: =IFERROR(C19- (C22+C25), 0) -> 45676.28 | D28: =IFERROR(D19- (D22+D25), 0) -> 35778.58 | E28: =IFERROR(E19- (E22+E25), 0) -> 35522.39 | F28: =IFERROR(F19- (F22+F25), 0) -> 28558.97 | G28: =IFERROR(G19- (G22+G25), 0) -> 19756.91 | H28: =IFERROR(H19- (H22+H25), 0) -> 28292.03 | I28: =IFERROR(I19- (I22+I25), 0) -> 21381.06 | J28: =IFERROR(J19- (J22+J25), 0) -> 30384.66 | ... M28: =IFERROR(M19- (M22+M25), 0) -> 24438
B29: EBT as a % of Sales | C29: =IFERROR(C28/C7,0) -> 0.16728444 | D29: =IFERROR(D28/D7,0) -> 0.13266434 | E29: =IFERROR(E28/E7,0) -> 0.12183959 | F29: =IFERROR(F28/F7,0) -> 0.094585419 | G29: =IFERROR(G28/G7,0) -> 0.075677265 | H29: =IFERROR(H28/H7,0) -> 0.11326111 | I29: =IFERROR(I28/I7,0) -> 0.076784996 | J29: =IFERROR(J28/J7,0) -> 0.08782532 | ... M29: =IFERROR(M28/M7,0) -> 0.055798597
B31: Tax | C31: =IFERROR('Data Sheet'!B29,0) -> 3025.05 | D31: =IFERROR('Data Sheet'!C29,0) -> 3251.23 | E31: =IFERROR('Data Sheet'!D29,0) -> 4341.93 | F31: =IFERROR('Data Sheet'!E29,0) -> -2437.45 | G31: =IFERROR('Data Sheet'!F29,0) -> 395.25 | H31: =IFERROR('Data Sheet'!G29,0) -> 2541.86 | I31: =IFERROR('Data Sheet'!H29,0) -> 4231.29 | J31: =IFERROR('Data Sheet'!I29,0) -> 704.06 | ... L31: =IFERROR('Data Sheet'!K29,0) -> 10502 | M31: =IFERROR(SUM('Data Sheet'!H48:K48),0) -> 8943
B32: Effective Tax Rate | C32: =C31/C28 -> 0.066228029 | D32: =D31/D28 -> 0.090870851 | E32: =E31/E28 -> 0.1222308 | F32: =F31/F28 -> -0.085347966 | G32: =G31/G28 -> 0.020005659 | H32: =H31/H28 -> 0.089843677 | I32: =I31/I28 -> 0.19789898 | J32: =J31/J28 -> 0.023171561 | ... M32: =M31/M28 -> 0.36594648
B34: Net Profit | C34: =IFERROR(C28-C31,0) -> 42651.23 | D34: =IFERROR(D28-D31,0) -> 32527.35 | E34: =IFERROR(E28-E31,0) -> 31180.46 | F34: =IFERROR(F28-F31,0) -> 30996.42 | G34: =IFERROR(G28-G31,0) -> 19361.66 | H34: =IFERROR(H28-H31,0) -> 25750.17 | I34: =IFERROR(I28-I31,0) -> 17149.77 | J34: =IFERROR(J28-J31,0) -> 29680.6 | ... M34: =IFERROR(M28-M31,0) -> 15495
B35: Net Margins | C35: =C34/C7 -> 0.15620552 | D35: =D34/D7 -> 0.12060902 | E35: =E34/E7 -> 0.10694704 | F35: =F34/F7 -> 0.10265809 | G35: =G34/G7 -> 0.074163292 | H35: =H34/H7 -> 0.10308531 | I35: =I34/I7 -> 0.061589323 | J35: =J34/J7 -> 0.085790271 | ... M35: =M34/M7 -> 0.035379297
B37: No. of Equity Shares | C37: =IFERROR('Data Sheet'!B93,0) -> 288.72 | D37: =IFERROR('Data Sheet'!C93,0) -> 288.73 | E37: =IFERROR('Data Sheet'!D93,0) -> 288.73 | F37: =IFERROR('Data Sheet'!E93,0) -> 288.73 | G37: =IFERROR('Data Sheet'!F93,0) -> 308.9 | H37: =IFERROR('Data Sheet'!G93,0) -> 332.03 | I37: =IFERROR('Data Sheet'!H93,0) -> 332.07 | J37: =IFERROR('Data Sheet'!I93,0) -> 332.13 | ... L37: =IFERROR('Data Sheet'!K93,0) -> 368.13
B38: Earning Per Share | C38: =C34/C37 -> 147.72524 | D38: =D34/D37 -> 112.65663 | E38: =E34/E37 -> 107.99176 | F38: =F34/F37 -> 107.35434 | G38: =G34/G37 -> 62.679378 | H38: =H34/H37 -> 77.553745 | I38: =I34/I37 -> 51.645045 | J38: =J34/J37 -> 89.364406 | ... L38: =L34/L37 -> 174.23736
B39: Earning Growth % | D39: =IFERROR(D38/C38-1,0) -> -0.23739073 | E39: =IFERROR(E38/D38-1,0) -> -0.041407923 | F39: =IFERROR(F38/E38-1,0) -> -0.0059024145 | G39: =IFERROR(G38/F38-1,0) -> -0.41614493 | H39: =IFERROR(H38/G38-1,0) -> 0.23730878 | I39: =IFERROR(I38/H38-1,0) -> -0.33407414 | J39: =IFERROR(J38/I38-1,0) -> 0.73035779 | K39: =IFERROR(K38/J38-1,0) -> 1.3232405 | ... M39: =IFERROR(M38/L38-1,0) -> -1
B41: Dividend Per Share | C41: =IFERROR('Data Sheet'!B31/'Financials>'!C37,0) -> 0.23524522 | D41: =IFERROR('Data Sheet'!C31/'Financials>'!D37,0) -> 0 | E41: =IFERROR('Data Sheet'!D31/'Financials>'!E37,0) -> 0 | F41: =IFERROR('Data Sheet'!E31/'Financials>'!F37,0) -> 0 | G41: =IFERROR('Data Sheet'!F31/'Financials>'!G37,0) -> 0 | H41: =IFERROR('Data Sheet'!G31/'Financials>'!H37,0) -> 0 | I41: =IFERROR('Data Sheet'!H31/'Financials>'!I37,0) -> 0 | J41: =IFERROR('Data Sheet'!I31/'Financials>'!J37,0) -> 2.3063861 | ... M41: =IFERROR('Data Sheet'!L31/'Financials>'!M37,0) -> 0
B42: Dividend Payout Ratio | C42: =IFERROR(C41/C38,0) -> 0.0015924511 | D42: =IFERROR(D41/D38,0) -> 0 | E42: =IFERROR(E41/E38,0) -> 0 | F42: =IFERROR(F41/F38,0) -> 0 | G42: =IFERROR(G41/G38,0) -> 0 | H42: =IFERROR(H41/H38,0) -> 0 | I42: =IFERROR(I41/I38,0) -> 0 | J42: =IFERROR(J41/J38,0) -> 0.025808777 | ... M42: =IFERROR(M41/M38,0) -> 0
B44: Retained Earnings | C44: =IFERROR(IF(C38>C41,1-C42,0),0) -> 0.99840755 | D44: =IFERROR(IF(D38>D41,1-D42,0),0) -> 1 | E44: =IFERROR(IF(E38>E41,1-E42,0),0) -> 1 | F44: =IFERROR(IF(F38>F41,1-F42,0),0) -> 1 | G44: =IFERROR(IF(G38>G41,1-G42,0),0) -> 1 | H44: =IFERROR(IF(H38>H41,1-H42,0),0) -> 1 | I44: =IFERROR(IF(I38>I41,1-I42,0),0) -> 1 | J44: =IFERROR(IF(J38>J41,1-J42,0),0) -> 0.97419122 | ... M44: =IFERROR(IF(M38>M41,1-M42,0),0) -> 0
A46: x | B46: Balance Sheet
B48: Equity Share Capital | C48: =IFERROR('Data Sheet'!B57,0) -> 679.18 | D48: =IFERROR('Data Sheet'!C57,0) -> 679.22 | E48: =IFERROR('Data Sheet'!D57,0) -> 679.22 | F48: =IFERROR('Data Sheet'!E57,0) -> 679.22 | G48: =IFERROR('Data Sheet'!F57,0) -> 719.54 | H48: =IFERROR('Data Sheet'!G57,0) -> 765.81 | I48: =IFERROR('Data Sheet'!H57,0) -> 765.88 | J48: =IFERROR('Data Sheet'!I57,0) -> 766.02 | ... L48: =IFERROR('Data Sheet'!K57,0) -> 736
B49: Reserves | C49: =IFERROR('Data Sheet'!B58,0) -> 78273.23 | D49: =IFERROR('Data Sheet'!C58,0) -> 57382.67 | E49: =IFERROR('Data Sheet'!D58,0) -> 94748.69 | F49: =IFERROR('Data Sheet'!E58,0) -> 59500.34 | G49: =IFERROR('Data Sheet'!F58,0) -> 62358.99 | H49: =IFERROR('Data Sheet'!G58,0) -> 54480.91 | I49: =IFERROR('Data Sheet'!H58,0) -> 43795.36 | J49: =IFERROR('Data Sheet'!I58,0) -> 44555.77 | ... L49: =IFERROR('Data Sheet'!K58,0) -> 115408
B50: Borrowings | C50: =IFERROR('Data Sheet'!B59,0) -> 69359.96 | D50: =IFERROR('Data Sheet'!C59,0) -> 78603.98 | E50: =IFERROR('Data Sheet'!D59,0) -> 88950.47 | F50: =IFERROR('Data Sheet'!E59,0) -> 106175.34 | G50: =IFERROR('Data Sheet'!F59,0) -> 124787.64 | H50: =IFERROR('Data Sheet'!G59,0) -> 142130.57 | I50: =IFERROR('Data Sheet'!H59,0) -> 146449.03 | J50: =IFERROR('Data Sheet'!I59,0) -> 134113.44 | ... L50: =IFERROR('Data Sheet'!K59,0) -> 71540
B51: Other Liabilities | C51: =IFERROR('Data Sheet'!B60,0) -> 114871.75 | D51: =IFERROR('Data Sheet'!C60,0) -> 135914.49 | E51: =IFERROR('Data Sheet'!D60,0) -> 142813.43 | F51: =IFERROR('Data Sheet'!E60,0) -> 139348.59 | G51: =IFERROR('Data Sheet'!F60,0) -> 132313.22 | H51: =IFERROR('Data Sheet'!G60,0) -> 144192.62 | I51: =IFERROR('Data Sheet'!H60,0) -> 138051.22 | J51: =IFERROR('Data Sheet'!I60,0) -> 155239.2 | ... L51: =IFERROR('Data Sheet'!K60,0) -> 189289
B52: Total Liabilities | C52: =IFERROR('Data Sheet'!B61,0) -> 263184.12 | D52: =IFERROR('Data Sheet'!C61,0) -> 272580.36 | E52: =IFERROR('Data Sheet'!D61,0) -> 327191.81 | F52: =IFERROR('Data Sheet'!E61,0) -> 305703.49 | G52: =IFERROR('Data Sheet'!F61,0) -> 320179.39 | H52: =IFERROR('Data Sheet'!G61,0) -> 341569.91 | I52: =IFERROR('Data Sheet'!H61,0) -> 329061.49 | J52: =IFERROR('Data Sheet'!I61,0) -> 334674.43 | ... L52: =IFERROR('Data Sheet'!K61,0) -> 376973
B54: Fixed Assest Net Block | C54: =IFERROR('Data Sheet'!B62,0) -> 107231.76 | D54: =IFERROR('Data Sheet'!C62,0) -> 95944.08 | E54: =IFERROR('Data Sheet'!D62,0) -> 121413.86 | F54: =IFERROR('Data Sheet'!E62,0) -> 111234.47 | G54: =IFERROR('Data Sheet'!F62,0) -> 127107.14 | H54: =IFERROR('Data Sheet'!G62,0) -> 138707.61 | I54: =IFERROR('Data Sheet'!H62,0) -> 138855.45 | J54: =IFERROR('Data Sheet'!I62,0) -> 132079.76 | ... L54: =IFERROR('Data Sheet'!K62,0) -> 115697
B55: Capital Work in Progress | C55: =IFERROR('Data Sheet'!B63,0) -> 25918.94 | D55: =IFERROR('Data Sheet'!C63,0) -> 33698.84 | E55: =IFERROR('Data Sheet'!D63,0) -> 40033.5 | F55: =IFERROR('Data Sheet'!E63,0) -> 31883.84 | G55: =IFERROR('Data Sheet'!F63,0) -> 35622.29 | H55: =IFERROR('Data Sheet'!G63,0) -> 20963.93 | I55: =IFERROR('Data Sheet'!H63,0) -> 10251.09 | J55: =IFERROR('Data Sheet'!I63,0) -> 14274.5 | ... L55: =IFERROR('Data Sheet'!K63,0) -> 65806
B56: Investments | C56: =IFERROR('Data Sheet'!B64,0) -> 23767.02 | D56: =IFERROR('Data Sheet'!C64,0) -> 20337.92 | E56: =IFERROR('Data Sheet'!D64,0) -> 20812.75 | F56: =IFERROR('Data Sheet'!E64,0) -> 15770.72 | G56: =IFERROR('Data Sheet'!F64,0) -> 16308.48 | H56: =IFERROR('Data Sheet'!G64,0) -> 24620.28 | I56: =IFERROR('Data Sheet'!H64,0) -> 29379.53 | J56: =IFERROR('Data Sheet'!I64,0) -> 26379.16 | ... L56: =IFERROR('Data Sheet'!K64,0) -> 35656
B57: Other Assets | C57: =IFERROR('Data Sheet'!B65 - SUM(C60:C62),0) -> 29579.36 | D57: =IFERROR('Data Sheet'!C65 - SUM(D60:D62),0) -> 37360.78 | E57: =IFERROR('Data Sheet'!D65 - SUM(E60:E62),0) -> 48286.86 | F57: =IFERROR('Data Sheet'!E65 - SUM(F60:F62),0) -> 56155.74 | G57: =IFERROR('Data Sheet'!F65 - SUM(G60:G62),0) -> 58784.94 | H57: =IFERROR('Data Sheet'!G65 - SUM(H60:H62),0) -> 61717.96 | I57: =IFERROR('Data Sheet'!H65 - SUM(I60:I62),0) -> 62223.77 | J57: =IFERROR('Data Sheet'!I65 - SUM(J60:J62),0) -> 68432.09 | ... L57: =IFERROR('Data Sheet'!K65 - SUM(L60:L62),0) -> 58463
B58: Total Non Current Assests | C58: =SUM(C54:C57) -> 186497.08 | D58: =SUM(D54:D57) -> 187341.62 | E58: =SUM(E54:E57) -> 230546.97 | F58: =SUM(F54:F57) -> 215044.77 | G58: =SUM(G54:G57) -> 237822.85 | H58: =SUM(H54:H57) -> 246009.78 | I58: =SUM(I54:I57) -> 240709.84 | J58: =SUM(J54:J57) -> 241165.51 | ... L58: =SUM(L54:L57) -> 275622
...

Sheet Ratio Analysis
B2: ="Ratio Analysis - "&UPDATE -> Ratio Analysis - Tata Motors
B3: Years | C3: ='Data Sheet'!B16 -> 42460 | D3: ='Data Sheet'!C16 -> 42825 | E3: ='Data Sheet'!D16 -> 43190 | F3: ='Data Sheet'!E16 -> 43555 | G3: ='Data Sheet'!F16 -> 43921 | H3: ='Data Sheet'!G16 -> 44286 | I3: ='Data Sheet'!H16 -> 44651 | J3: ='Data Sheet'!I16 -> 45016 | ... L3: ='Data Sheet'!K16 -> 45747 | M3: Trends | N3: Mean | O3: Median
B5: Sales Growth | C5: ='Financials>'!C8 -> - | D5: ='Financials>'!D8 -> -0.01228033 | E5: ='Financials>'!E8 -> 0.081047746 | F5: ='Financials>'!F8 -> 0.035629919 | G5: ='Financials>'!G8 -> -0.13536016 | H5: ='Financials>'!H8 -> -0.043181168 | I5: ='Financials>'!I8 -> 0.11472967 | J5: ='Financials>'!J8 -> 0.24245815 | ... L5: ='Financials>'!L8 -> 0.013084771 | N5: =IFERROR(AVERAGE(D5:L5), 0) -> 0.061181096 | O5: =IFERROR(MEDIAN(C5:L5), 0) -> 0.035629919
B6: EBITDA Growth | C6: =IFERROR('Financials>'!C19/'Financials>'!B19 - 1, "-") -> - | D6: =IFERROR('Financials>'!D19/'Financials>'!C19 - 1, "-") -> -0.13904722 | E6: =IFERROR('Financials>'!E19/'Financials>'!D19 - 1, "-") -> 0.066230755 | F6: =IFERROR('Financials>'!F19/'Financials>'!E19 - 1, "-") -> -0.062333371 | G6: =IFERROR('Financials>'!G19/'Financials>'!F19 - 1, "-") -> -0.16375107 | H6: =IFERROR('Financials>'!H19/'Financials>'!G19 - 1, "-") -> 0.23768881 | I6: =IFERROR('Financials>'!I19/'Financials>'!H19 - 1, "-") -> -0.073533546 | J6: =IFERROR('Financials>'!J19/'Financials>'!I19 - 1, "-") -> 0.17904086 | ... L6: =IFERROR('Financials>'!L19/'Financials>'!K19 - 1, "-") -> 0.031749053 | N6: =IFERROR(AVERAGE(D6:L6), 0) -> 0.066734308 | O6: =IFERROR(MEDIAN(C6:L6), 0) -> 0.031749053
B7: EBT Growth | C7: =IFERROR('Financials>'!C28/'Financials>'!B28-1,"-") -> - | D7: =IFERROR('Financials>'!D28/'Financials>'!C28-1,"-") -> -0.21669234 | E7: =IFERROR('Financials>'!E28/'Financials>'!D28-1,"-") -> -0.0071604295 | F7: =IFERROR('Financials>'!F28/'Financials>'!E28-1,"-") -> -0.19602904 | G7: =IFERROR('Financials>'!G28/'Financials>'!F28-1,"-") -> -0.30820649 | H7: =IFERROR('Financials>'!H28/'Financials>'!G28-1,"-") -> 0.43200683 | I7: =IFERROR('Financials>'!I28/'Financials>'!H28-1,"-") -> -0.24427268 | J7: =IFERROR('Financials>'!J28/'Financials>'!I28-1,"-") -> 0.42110167 | ... L7: =IFERROR('Financials>'!L28/'Financials>'!K28-1,"-") -> 0.14870501 | N7: =IFERROR(AVERAGE(D7:L7), 0) -> 0.12978495 | O7: =IFERROR(MEDIAN(C7:L7), 0) -> -0.0071604295
B8: Net Profit Growth | C8: =IFERROR('Financials>'!C34/'Financials>'!B34 - 1, "-") -> - | D8: =IFERROR('Financials>'!D34/'Financials>'!C34 - 1, "-") -> -0.23736432 | E8: =IFERROR('Financials>'!E34/'Financials>'!D34 - 1, "-") -> -0.041407923 | F8: =IFERROR('Financials>'!F34/'Financials>'!E34 - 1, "-") -> -0.0059024145 | G8: =IFERROR('Financials>'!G34/'Financials>'!F34 - 1, "-") -> -0.37535819 | H8: =IFERROR('Financials>'!H34/'Financials>'!G34 - 1, "-") -> 0.32995673 | I8: =IFERROR('Financials>'!I34/'Financials>'!H34 - 1, "-") -> -0.33399391 | J8: =IFERROR('Financials>'!J34/'Financials>'!I34 - 1, "-") -> 0.73067044 | ... L8: =IFERROR('Financials>'!L34/'Financials>'!K34 - 1, "-") -> -0.070473154 | N8: =IFERROR(AVERAGE(D8:L8), 0) -> 0.14678295 | O8: =IFERROR(MEDIAN(C8:L8), 0) -> -0.041407923
B9: Dividend Growth | C9: =IFERROR('Financials>'!C41/'Financials>'!B41 - 1, "-") -> - | D9: =IFERROR('Financials>'!D41/'Financials>'!C41 - 1, "-") -> -1 | E9: =IFERROR('Financials>'!E41/'Financials>'!D41 - 1, "-") -> - | F9: =IFERROR('Financials>'!F41/'Financials>'!E41 - 1, "-") -> - | G9: =IFERROR('Financials>'!G41/'Financials>'!F41 - 1, "-") -> - | H9: =IFERROR('Financials>'!H41/'Financials>'!G41 - 1, "-") -> - | I9: =IFERROR('Financials>'!I41/'Financials>'!H41 - 1, "-") -> - | J9: =IFERROR('Financials>'!J41/'Financials>'!I41 - 1, "-") -> - | ... L9: =IFERROR('Financials>'!L41/'Financials>'!K41 - 1, "-") -> -0.1336307 | N9: =IFERROR(AVERAGE(D9:L9), 0) -> 0.2893461 | O9: =IFERROR(MEDIAN(C9:L9), 0) -> -0.1336307
B11: Gross Margin | C11: =IFERROR('Financials>'!C14, "0") -> 0.35311838 | D11: =IFERROR('Financials>'!D14, "0") -> 0.34324706 | E11: =IFERROR('Financials>'!E14, "0") -> 0.32042732 | F11: =IFERROR('Financials>'!F14, "0") -> 0.30581317 | G11: =IFERROR('Financials>'!G14, "0") -> 0.3107639 | H11: =IFERROR('Financials>'!H14, "0") -> 0.32873865 | I11: =IFERROR('Financials>'!I14, "0") -> 0.30871256 | J11: =IFERROR('Financials>'!J14, "0") -> 0.30412739 | ... L11: =IFERROR('Financials>'!L14, "0") -> 0.33353347 | N11: =IFERROR(AVERAGE(C11:L11), 0) -> 0.32347971 | O11: =IFERROR(MEDIAN(C11:L11),0) -> 0.32337124
B12: EBITDA Margin | C12: =IFERROR('Financials>'!C20, "-") -> 0.24639159 | D12: =IFERROR('Financials>'!D20, "-") -> 0.21476896 | E12: =IFERROR('Financials>'!E20, "-") -> 0.21182531 | F12: =IFERROR('Financials>'!F20, "-") -> 0.19178813 | G12: =IFERROR('Financials>'!G20, "-") -> 0.18549066 | H12: =IFERROR('Financials>'!H20, "-") -> 0.23994063 | I12: =IFERROR('Financials>'!I20, "-") -> 0.19941781 | J12: =IFERROR('Financials>'!J20, "-") -> 0.18923916 | ... L12: =IFERROR('Financials>'!L20, "-") -> 0.23421463 | N12: =IFERROR(AVERAGE(C12:L12), 0) -> 0.21430546 | O12: =IFERROR(MEDIAN(C12:L12),0) -> 0.21329713
B13: EBIT Margin | C13: =IFERROR(('Financials>'!C19 - 'Financials>'!C25)/'Financials>'!C7, "-") -> 0.18519017 | D13: =IFERROR(('Financials>'!D19 - 'Financials>'!D25)/'Financials>'!D7, "-") -> 0.14837857 | E13: =IFERROR(('Financials>'!E19 - 'Financials>'!E25)/'Financials>'!E7, "-") -> 0.13789784 | F13: =IFERROR(('Financials>'!F19 - 'Financials>'!F25)/'Financials>'!F7, "-") -> 0.11365752 | G13: =IFERROR(('Financials>'!G19 - 'Financials>'!G25)/'Financials>'!G7, "-") -> 0.10342226 | H13: =IFERROR(('Financials>'!H19 - 'Financials>'!H25)/'Financials>'!H7, "-") -> 0.1456764 | I13: =IFERROR(('Financials>'!I19 - 'Financials>'!I25)/'Financials>'!I7, "-") -> 0.11022633 | J13: =IFERROR(('Financials>'!J19 - 'Financials>'!J25)/'Financials>'!J7, "-") -> 0.11738155 | ... L13: =IFERROR(('Financials>'!L19 - 'Financials>'!L25)/'Financials>'!L7, "-") -> 0.18132342 | N13: =IFERROR(AVERAGE(C13:L13), 0) -> 0.14103714 | O13: =IFERROR(MEDIAN(C13:L13),0) -> 0.14178712
B14: EBT Margin | C14: ='Financials>'!C29 -> 0.16728444 | D14: ='Financials>'!D29 -> 0.13266434 | E14: ='Financials>'!E29 -> 0.12183959 | F14: ='Financials>'!F29 -> 0.094585419 | G14: ='Financials>'!G29 -> 0.075677265 | H14: ='Financials>'!H29 -> 0.11326111 | I14: ='Financials>'!I29 -> 0.076784996 | J14: ='Financials>'!J29 -> 0.08782532 | ... L14: ='Financials>'!L29 -> 0.16976313 | N14: =IFERROR(AVERAGE(C14:L14), 0) -> 0.11894059 | O14: =IFERROR(MEDIAN(C14:L14),0) -> 0.11755035
B15: Net Profit Margin | C15: ='Financials>'!C35 -> 0.15620552 | D15: ='Financials>'!D35 -> 0.12060902 | E15: ='Financials>'!E35 -> 0.10694704 | F15: ='Financials>'!F35 -> 0.10265809 | G15: ='Financials>'!G35 -> 0.074163292 | H15: ='Financials>'!H35 -> 0.10308531 | I15: ='Financials>'!I35 -> 0.061589323 | J15: ='Financials>'!J35 -> 0.085790271 | ... L15: ='Financials>'!L35 -> 0.14587839 | N15: =IFERROR(AVERAGE(C15:L15), 0) -> 0.11159181 | O15: =IFERROR(MEDIAN(C15:L15),0) -> 0.10501618
B17: Sales Expenses% of Sales | C17: =IFERROR('Financials>'!C17, "-") -> 0.10672679 | D17: =IFERROR('Financials>'!D17, "-") -> 0.1284781 | E17: =IFERROR('Financials>'!E17, "-") -> 0.10860202 | F17: =IFERROR('Financials>'!F17, "-") -> 0.11402505 | G17: =IFERROR('Financials>'!G17, "-") -> 0.12527324 | H17: =IFERROR('Financials>'!H17, "-") -> 0.088798023 | I17: =IFERROR('Financials>'!I17, "-") -> 0.10929475 | J17: =IFERROR('Financials>'!J17, "-") -> 0.11488822 | ... L17: =IFERROR('Financials>'!L17, "-") -> 0.099318846 | N17: =IFERROR(AVERAGE(C17:L17), 0) -> 0.10917425 | O17: =IFERROR(MEDIAN(C17:L17),0) -> 0.10894839
B18: Depriciation% of Sales | C18: =IFERROR('Financials>'!C26,"-") -> 0.061201426 | D18: =IFERROR('Financials>'!D26,"-") -> 0.066390387 | E18: =IFERROR('Financials>'!E26,"-") -> 0.073927472 | F18: =IFERROR('Financials>'!F26,"-") -> 0.078130605 | G18: =IFERROR('Financials>'!G26,"-") -> 0.082068398 | H18: =IFERROR('Financials>'!H26,"-") -> 0.094264231 | I18: =IFERROR('Financials>'!I26,"-") -> 0.089191478 | J18: =IFERROR('Financials>'!J26,"-") -> 0.071857611 | ... L18: =IFERROR('Financials>'!L26,"-") -> 0.052891209 | N18: =IFERROR(AVERAGE(C18:L18), 0) -> 0.073268318 | O18: =IFERROR(MEDIAN(C18:L18),0) -> 0.072892542
B19: Operating Income% of Sales | C19: =C13 -> 0.18519017 | D19: =D13 -> 0.14837857 | E19: =E13 -> 0.13789784 | F19: =F13 -> 0.11365752 | G19: =G13 -> 0.10342226 | H19: =H13 -> 0.1456764 | I19: =I13 -> 0.11022633 | J19: =J13 -> 0.11738155 | ... L19: =L13 -> 0.18132342 | N19: =IFERROR(AVERAGE(C19:L19), 0) -> 0.14103714 | O19: =IFERROR(MEDIAN(C19:L19),0) -> 0.14178712
B21: Return on Capital Employed | C21: =('Financials>'!C19 -'Financials>'!C25)/SUM('Financials>'!C48:C50) -> 0.34093825 | D21: =('Financials>'!D19 -'Financials>'!D25)/SUM('Financials>'!D48:D50) -> 0.29280602 | E21: =('Financials>'!E19 -'Financials>'!E25)/SUM('Financials>'!E48:E50) -> 0.21805257 | F21: =('Financials>'!F19 -'Financials>'!F25)/SUM('Financials>'!F48:F50) -> 0.20629131 | G21: =('Financials>'!G19 -'Financials>'!G25)/SUM('Financials>'!G48:G50) -> 0.14372061 | H21: =('Financials>'!H19 -'Financials>'!H25)/SUM('Financials>'!H48:H50) -> 0.18436366 | I21: =('Financials>'!I19 -'Financials>'!I25)/SUM('Financials>'!I48:I50) -> 0.16068728 | J21: =('Financials>'!J19 -'Financials>'!J25)/SUM('Financials>'!J48:J50) -> 0.226322 | ... L21: =('Financials>'!L19 -'Financials>'!L25)/SUM('Financials>'!L48:L50) -> 0.4247938 | N21: =IFERROR(AVERAGE(C21:L21), 0) -> 0.25756123 | O21: =IFERROR(MEDIAN(C21:L21),0) -> 0.22218729 | Q21: EBIT/(EQ+DEBT) or EBIT/ Equity + Reserves + Borrowings
B22: Retained Earnings% | C22: ='Financials>'!C44 -> 0.99840755 | D22: ='Financials>'!D44 -> 1 | E22: ='Financials>'!E44 -> 1 | F22: ='Financials>'!F44 -> 1 | G22: ='Financials>'!G44 -> 1 | H22: ='Financials>'!H44 -> 1 | I22: ='Financials>'!I44 -> 1 | J22: ='Financials>'!J44 -> 0.97419122 | ... L22: ='Financials>'!L44 -> 0.96557638 | N22: =IFERROR(AVERAGE(C22:L22), 0) -> 0.99048297 | O22: =IFERROR(MEDIAN(C22:L22),0) -> 1
B23: Return on Equity% | C23: =IFERROR('Financials>'!C34/SUM('Financials>'!C48:C49), "-") -> 0.54021442 | D23: =IFERROR('Financials>'!D34/SUM('Financials>'!D48:D49), "-") -> 0.56021859 | E23: =IFERROR('Financials>'!E34/SUM('Financials>'!E48:E49), "-") -> 0.32674361 | F23: =IFERROR('Financials>'!F34/SUM('Financials>'!F48:F49), "-") -> 0.51506558 | G23: =IFERROR('Financials>'!G34/SUM('Financials>'!G48:G49), "-") -> 0.30694533 | H23: =IFERROR('Financials>'!H34/SUM('Financials>'!H48:H49), "-") -> 0.4660941 | I23: =IFERROR('Financials>'!I34/SUM('Financials>'!I48:I49), "-") -> 0.38485846 | J23: =IFERROR('Financials>'!J34/SUM('Financials>'!J48:J49), "-") -> 0.65488587 | ... L23: =IFERROR('Financials>'!L34/SUM('Financials>'!L48:L49), "-") -> 0.55226271 | N23: =IFERROR(AVERAGE(C23:L23), 0) -> 0.51198961 | O23: =IFERROR(MEDIAN(C23:L23),0) -> 0.52764 | Q23: Net Profit/ Shareholder funds (Share equity Capital + Reserves)
B24: Self Sustain Growth Rate | C24: =C22*C23 -> 0.53935415 | D24: =D22*D23 -> 0.56021859 | E24: =E22*E23 -> 0.32674361 | F24: =F22*F23 -> 0.51506558 | G24: =G22*G23 -> 0.30694533 | H24: =H22*H23 -> 0.4660941 | I24: =I22*I23 -> 0.38485846 | J24: =J22*J23 -> 0.63798407 | ... L24: =L22*L23 -> 0.53325183 | N24: =IFERROR(AVERAGE(C24:L24), 0) -> 0.50560264 | O24: =IFERROR(MEDIAN(C24:L24),0) -> 0.5241587 | Q24: G = B * R
B25: Interest Covering Ratio | C25: =('Financials>'!C19-'Financials>'!C25)/'Financials>'!C22 -> 10.34251 | D25: =('Financials>'!D19-'Financials>'!D25)/'Financials>'!D22 -> 9.4423066 | E25: =('Financials>'!E19-'Financials>'!E25)/'Financials>'!E22 -> 8.5873523 | F25: =('Financials>'!F19-'Financials>'!F25)/'Financials>'!F22 -> 5.9593599 | G25: =('Financials>'!G19-'Financials>'!G25)/'Financials>'!G22 -> 3.7276004 | H25: =('Financials>'!H19-'Financials>'!H25)/'Financials>'!H22 -> 4.494064 | I25: =('Financials>'!I19-'Financials>'!I25)/'Financials>'!I22 -> 3.2961106 | J25: =('Financials>'!J19-'Financials>'!J25)/'Financials>'!J22 -> 3.9714654 | ... L25: =('Financials>'!L19-'Financials>'!L25)/'Financials>'!L22 -> 15.685029 | N25: =IFERROR(AVERAGE(C25:L25), 0) -> 7.5062685 | O25: =IFERROR(MEDIAN(C25:L25),0) -> 7.2733561 | Q25: How much money do you have before interest so that you can pay interest for n times
B27: Debtor Turnover Ratio | C27: =IFERROR('Financials>'!C7/'Financials>'!C60, "-") -> 20.119918 | D27: =IFERROR('Financials>'!D7/'Financials>'!D60, "-") -> 19.160353 | E27: =IFERROR('Financials>'!E7/'Financials>'!E60, "-") -> 14.655712 | F27: =IFERROR('Financials>'!F7/'Financials>'!F60, "-") -> 15.894699 | G27: =IFERROR('Financials>'!G7/'Financials>'!G60, "-") -> 23.366617 | H27: =IFERROR('Financials>'!H7/'Financials>'!H60, "-") -> 19.701331 | I27: =IFERROR('Financials>'!I7/'Financials>'!I60, "-") -> 22.379918 | J27: =IFERROR('Financials>'!J7/'Financials>'!J60, "-") -> 21.982948 | ... L27: =IFERROR('Financials>'!L7/'Financials>'!L60, "-") -> 33.189538 | N27: =IFERROR(AVERAGE(C27:L27), 0) -> 21.605368 | O27: =IFERROR(MEDIAN(C27:L27),0) -> 21.051433 | Q27: Sales/Debtor (Recievables)
B28: Creditor Turnover Ratio | C28: =IFERROR('Financials>'!C7/'Financials>'!C51, "-") -> 2.3769604 | D28: =IFERROR('Financials>'!D7/'Financials>'!D51, "-") -> 1.9842808 | E28: =IFERROR('Financials>'!E7/'Financials>'!E51, "-") -> 2.041478 | F28: =IFERROR('Financials>'!F7/'Financials>'!F51, "-") -> 2.1667848 | G28: =IFERROR('Financials>'!G7/'Financials>'!G51, "-") -> 1.9731057 | H28: =IFERROR('Financials>'!H7/'Financials>'!H51, "-") -> 1.7323685 | I28: =IFERROR('Financials>'!I7/'Financials>'!I51, "-") -> 2.0170312 | J28: =IFERROR('Financials>'!J7/'Financials>'!J51, "-") -> 2.2286057 | ... L28: =IFERROR('Financials>'!L7/'Financials>'!L51, "-") -> 2.3228767 | N28: =IFERROR(AVERAGE(C28:L28), 0) -> 2.1290872 | O28: =IFERROR(MEDIAN(C28:L28),0) -> 2.1041314 | Q28: Payables * (x) = Sales
B29: Inventory Turnover Ratio | C29: =IFERROR('Financials>'!C7/'Financials>'!C61, "-") -> 8.3613381 | D29: =IFERROR('Financials>'!D7/'Financials>'!D61, "-") -> 7.6867643 | E29: =IFERROR('Financials>'!E7/'Financials>'!E61, "-") -> 6.9190052 | F29: =IFERROR('Financials>'!F7/'Financials>'!F61, "-") -> 7.7392856 | G29: =IFERROR('Financials>'!G7/'Financials>'!G61, "-") -> 6.9698269 | H29: =IFERROR('Financials>'!H7/'Financials>'!H61, "-") -> 6.9217099 | I29: =IFERROR('Financials>'!I7/'Financials>'!I61, "-") -> 7.9015588 | J29: =IFERROR('Financials>'!J7/'Financials>'!J61, "-") -> 8.4888642 | ... L29: =IFERROR('Financials>'!L7/'Financials>'!L61, "-") -> 9.3019738 | N29: =IFERROR(AVERAGE(C29:L29), 0) -> 7.937244 | O29: =IFERROR(MEDIAN(C29:L29),0) -> 7.8204222 | Q29: Inventory * (x) = Sales
B30: Fixed Assets Turnover Ratio | C30: =IFERROR('Financials>'!C7/'Financials>'!C54, "-") -> 2.5463128 | D30: =IFERROR('Financials>'!D7/'Financials>'!D54, "-") -> 2.8109343 | E30: =IFERROR('Financials>'!E7/'Financials>'!E54, "-") -> 2.4012949 | F30: =IFERROR('Financials>'!F7/'Financials>'!F54, "-") -> 2.714432 | G30: =IFERROR('Financials>'!G7/'Financials>'!G54, "-") -> 2.0539206 | H30: =IFERROR('Financials>'!H7/'Financials>'!H54, "-") -> 1.8008727 | I30: =IFERROR('Financials>'!I7/'Financials>'!I54, "-") -> 2.0053489 | J30: =IFERROR('Financials>'!J7/'Financials>'!J54, "-") -> 2.6193792 | ... L30: =IFERROR('Financials>'!L7/'Financials>'!L54, "-") -> 3.800401 | N30: =IFERROR(AVERAGE(C30:L30), 0) -> 2.6331377 | O30: =IFERROR(MEDIAN(C30:L30),0) -> 2.582846 | Q30: Fixed Assests * (x) = Sales
B31: Capital Turnover Ratio | C31: =IFERROR('Financials>'!C7/SUM('Financials>'!C48:C49), "-") -> 3.4583567 | D31: =IFERROR('Financials>'!D7/SUM('Financials>'!D48:D49), "-") -> 4.6449144 | E31: =IFERROR('Financials>'!E7/SUM('Financials>'!E48:E49), "-") -> 3.0551909 | F31: =IFERROR('Financials>'!F7/SUM('Financials>'!F48:F49), "-") -> 5.0172916 | G31: =IFERROR('Financials>'!G7/SUM('Financials>'!G48:G49), "-") -> 4.138777 | H31: =IFERROR('Financials>'!H7/SUM('Financials>'!H48:H49), "-") -> 4.5214404 | I31: =IFERROR('Financials>'!I7/SUM('Financials>'!I48:I49), "-") -> 6.2487853 | J31: =IFERROR('Financials>'!J7/SUM('Financials>'!J48:J49), "-") -> 7.6335681 | ... L31: =IFERROR('Financials>'!L7/SUM('Financials>'!L48:L49), "-") -> 3.7857746 | N31: =IFERROR(AVERAGE(C31:L31), 0) -> 4.76151 | O31: =IFERROR(MEDIAN(C31:L31),0) -> 4.5831774 | Q31: Capital Turnover Ratio * (x) = Sales
B33: Debtor Days | C33: =IFERROR(365/C27, 0) -> 18.141227 | D33: =IFERROR(365/D27, 0) -> 19.049753 | E33: =IFERROR(365/E27, 0) -> 24.904965 | F33: =IFERROR(365/F27, 0) -> 22.963631 | G33: =IFERROR(365/G27, 0) -> 15.620575 | H33: =IFERROR(365/H27, 0) -> 18.526667 | I33: =IFERROR(365/I27, 0) -> 16.309265 | J33: =IFERROR(365/J27, 0) -> 16.603779 | ... L33: =IFERROR(365/L27, 0) -> 10.997441 | N33: =IFERROR(AVERAGE(C33:L33), 0) -> 17.737364 | O33: =IFERROR(MEDIAN(C33:L33),0) -> 17.372503
B34: Creditor Days | C34: =IFERROR(365/C28, 0) -> 153.55746 | D34: =IFERROR(365/D28, 0) -> 183.94574 | E34: =IFERROR(365/E28, 0) -> 178.79203 | F34: =IFERROR(365/F28, 0) -> 168.45236 | G34: =IFERROR(365/G28, 0) -> 184.98755 | H34: =IFERROR(365/H28, 0) -> 210.69421 | I34: =IFERROR(365/I28, 0) -> 180.95902 | J34: =IFERROR(365/J28, 0) -> 163.77953 | ... L34: =IFERROR(365/L28, 0) -> 157.13275 | N34: =IFERROR(AVERAGE(C34:L34), 0) -> 173.14397 | O34: =IFERROR(MEDIAN(C34:L34),0) -> 173.62219
B35: Inventory Days | C35: =IFERROR(365/C29, 0) -> 43.6533 | D35: =IFERROR(365/D29, 0) -> 47.484219 | E35: =IFERROR(365/E29, 0) -> 52.753249 | F35: =IFERROR(365/F29, 0) -> 47.161976 | G35: =IFERROR(365/G29, 0) -> 52.368589 | H35: =IFERROR(365/H29, 0) -> 52.732635 | I35: =IFERROR(365/I29, 0) -> 46.193417 | J35: =IFERROR(365/J29, 0) -> 42.997507 | ... L35: =IFERROR(365/L29, 0) -> 39.238984 | N35: =IFERROR(AVERAGE(C35:L35), 0) -> 46.477276 | O35: =IFERROR(MEDIAN(C35:L35),0) -> 46.677696
B36: Cash Conversion Cycle | C36: =SUM(C33,C35)-C34 -> -91.762933 | D36: =SUM(D33,D35)-D34 -> -117.41177 | E36: =SUM(E33,E35)-E34 -> -101.13382 | F36: =SUM(F33,F35)-F34 -> -98.326751 | G36: =SUM(G33,G35)-G34 -> -116.99839 | H36: =SUM(H33,H35)-H34 -> -139.4349 | I36: =SUM(I33,I35)-I34 -> -118.45634 | J36: =SUM(J33,J35)-J34 -> -104.17824 | ... L36: =SUM(L33,L35)-L34 -> -106.89633 | N36: =IFERROR(AVERAGE(C36:L36), 0) -> -108.92933 | O36: =IFERROR(MEDIAN(C36:L36),0) -> -105.53729
B38: CFO/Sales | C38: =IFERROR('Financials>'!C80/'Financials>'!C7, "0") -> 0.14360971 | D38: =IFERROR('Financials>'!D80/'Financials>'!D7, "0") -> 0.12404497 | E38: =IFERROR('Financials>'!E80/'Financials>'!E7, "0") -> 0.059759806 | F38: =IFERROR('Financials>'!F80/'Financials>'!F7, "0") -> 0.03865358 | G38: =IFERROR('Financials>'!G80/'Financials>'!G7, "0") -> 0.12141666 | H38: =IFERROR('Financials>'!H80/'Financials>'!H7, "0") -> 0.11572301 | I38: =IFERROR('Financials>'!I80/'Financials>'!I7, "0") -> 0.012684339 | J38: =IFERROR('Financials>'!J80/'Financials>'!J7, "0") -> 0.093248786 | ... L38: =IFERROR('Financials>'!L80/'Financials>'!L7, "0") -> 0.16206234 | N38: =IFERROR(AVERAGE(C38:L38), 0) -> 0.10445609 | O38: =IFERROR(MEDIAN(C38:L38),0) -> 0.11856983
B39: CFO/Total Assests | C39: =IFERROR('Financials>'!C80/'Financials>'!C65, "0") -> 0.14899075 | D39: =IFERROR('Financials>'!D80/'Financials>'!D65, "0") -> 0.12273078 | E39: =IFERROR('Financials>'!E80/'Financials>'!E65, "0") -> 0.05325011 | F39: =IFERROR('Financials>'!F80/'Financials>'!F65, "0") -> 0.038177516 | G39: =IFERROR('Financials>'!G80/'Financials>'!G65, "0") -> 0.099000751 | H39: =IFERROR('Financials>'!H80/'Financials>'!H65, "0") -> 0.08462982 | I39: =IFERROR('Financials>'!I80/'Financials>'!I65, "0") -> 0.010733556 | J39: =IFERROR('Financials>'!J80/'Financials>'!J65, "0") -> 0.096395174 | ... L39: =IFERROR('Financials>'!L80/'Financials>'!L65, "0") -> 0.1890268 | N39: =IFERROR(AVERAGE(C39:L39), 0) -> 0.10465502 | O39: =IFERROR(MEDIAN(C39:L39),0) -> 0.097697963
B40: CFO/Total Debt | C40: =IFERROR('Financials>'!C80/'Financials>'!C50, "0") -> 0.56534058 | D40: =IFERROR('Financials>'!D80/'Financials>'!D50, "0") -> 0.42560186 | E40: =IFERROR('Financials>'!E80/'Financials>'!E50, "0") -> 0.19587305 | F40: =IFERROR('Financials>'!F80/'Financials>'!F50, "0") -> 0.10992195 | G40: =IFERROR('Financials>'!G80/'Financials>'!G50, "0") -> 0.25401554 | H40: =IFERROR('Financials>'!H80/'Financials>'!H50, "0") -> 0.20338341 | I40: =IFERROR('Financials>'!I80/'Financials>'!I50, "0") -> 0.024117606 | J40: =IFERROR('Financials>'!J80/'Financials>'!J50, "0") -> 0.24055009 | ... L40: =IFERROR('Financials>'!L80/'Financials>'!L50, "0") -> 0.99605815 | N40: =IFERROR(AVERAGE(C40:L40), 0) -> 0.37163091 | O40: =IFERROR(MEDIAN(C40:L40),0) -> 0.24728282

Sheet Forecasting
B3: Year Weight | C3: Years | D3: Sales | E3: Growth
B4: 1 | C4: 2014 | D4: 232834
B5: =B4+1 -> 2 | C5: =C4+1 -> 2015 | D5: 263159 | E5: =D5/D4-1 -> 0.13024301
B6: =B5+1 -> 3 | C6: =C5+1 -> 2016 | D6: 273046 | E6: =D6/D5-1 -> 0.037570442 | I6: 13 | J6: 2026 | K6: =$I$35+B16*$I$36 -> 398918.7 | L6: =K6/D15-1 -> -0.0927377 | M6: Formula that is used here, = Intercept + Weight * Year Weight
B7: =B6+1 -> 4 | C7: =C6+1 -> 2017 | D7: 269693 | E7: =D7/D6-1 -> -0.012279982 | I7: 14 | J7: 2027 | K7: =$I$35+B17*$I$36 -> 413608.56 | L7: =K7/D16-1 -> 0.036824204
B8: =B7+1 -> 5 | C8: =C7+1 -> 2018 | D8: 291550 | E8: =D8/D7-1 -> 0.081044002 | I8: 15 | J8: 2028 | K8: =$I$35+B18*$I$36 -> 428298.42 | L8: =K8/D17-1 -> 0.035516343
B9: =B8+1 -> 6 | C9: =C8+1 -> 2019 | D9: 301938 | E9: =D9/D8-1 -> 0.035630252 | I9: 16 | J9: 2029 | K9: =$I$35+B19*$I$36 -> 442988.29 | L9: =K9/D18-1 -> 0.034298197
B10: =B9+1 -> 7 | C10: =C9+1 -> 2020 | D10: 261068 | E10: =D10/D9-1 -> -0.13535891 | I10: 17 | J10: 2030 | K10: =$I$35+B20*$I$36 -> 457678.15 | L10: =K10/D19-1 -> 0.03316084
B11: =B10+1 -> 8 | C11: =C10+1 -> 2021 | D11: 249795 | E11: =D11/D10-1 -> -0.043180321
B12: =B11+1 -> 9 | C12: =C11+1 -> 2022 | D12: 278454 | E12: =D12/D11-1 -> 0.11473008
B13: =B12+1 -> 10 | C13: =C12+1 -> 2023 | D13: 345967 | E13: =D13/D12-1 -> 0.24245656
B14: =B13+1 -> 11 | C14: =C13+1 -> 2024 | D14: 434016 | E14: =D14/D13-1 -> 0.25450115
B15: =B14+1 -> 12 | C15: =C14+1 -> 2025 | D15: 439695 | E15: =D15/D14-1 -> 0.013084771
B16: 13 | C16: =C15+1 -> 2026 | D16: =FORECAST(B16,$D$4:$D$15,$B$4:$B$15) -> 398918.7 | E16: =D16/D15-1 -> -0.0927377
B17: 14 | C17: =C16+1 -> 2027 | D17: =FORECAST(B17,$D$4:$D$15,$B$4:$B$15) -> 413608.56 | E17: =D17/D16-1 -> 0.036824204
B18: 15 | C18: =C17+1 -> 2028 | D18: =FORECAST(B18,$D$4:$D$15,$B$4:$B$15) -> 428298.42 | E18: =D18/D17-1 -> 0.035516343
B19: 16 | C19: =C18+1 -> 2029 | D19: =FORECAST(B19,$D$4:$D$15,$B$4:$B$15) -> 442988.29 | E19: =D19/D18-1 -> 0.034298197 | H19: SUMMARY OUTPUT
B20: 17 | C20: =C19+1 -> 2030 | D20: =FORECAST(B20,$D$4:$D$15,$B$4:$B$15) -> 457678.15 | E20: =D20/D19-1 -> 0.03316084
H21: Regression Statistics
H22: Multiple R | I22: 0.77380616
H23: R Square | I23: 0.59877597
H24: Adjusted R Square | I24: 0.55865356
B25: Arthimetic Mean (Growth) | C25: =AVERAGE(E5:E15) -> 0.065312823 | H25: Standard Error | I25: 45472.316
B26: Geometric Mean | C26: =_xlfn.RRI(B15,D4,D15) -> 0.054408166 | H26: Observations | I26: 12
B27: Harcoded Formula | C27: =(D15/D4)^(1/B15)-1 -> 0.054408166
H28: ANOVA
B29: Standard Deviation | C29: =_xlfn.STDEV.S(E5:E15) -> 0.11684032 | I29: df | J29: SS | K29: MS | L29: F | M29: Significance F
H30: Regression | I30: 1 | J30: 3.0858269e+10 | K30: 3.0858269e+10 | L30: 14.923731 | M30: 0.0031441948
H31: Residual | I31: 10 | J31: 2.0677315e+10 | K31: 2.0677315e+09
H32: Total | I32: 11 | J32: 5.1535584e+10
I34: Coefficients | J34: Standard Error | K34: t Stat | L34: P-value | M34: Lower 95% | N34: Upper 95% | O34: Lower 95.0% | P34: Upper 95.0%
H35: Intercept | I35: 207950.47 | J35: 27986.276 | K35: 7.4304446 | L35: 2.2349424e-05 | M35: 145593.16 | N35: 270307.78 | O35: 145593.16 | P35: 270307.78
H36: Year Weight | I36: 14689.864 | J36: 3802.5861 | K36: 3.8631246 | L36: 0.0031441948 | M36: 6217.1739 | N36: 23162.553 | O36: 6217.1739 | P36: 23162.553

Sheet WACC
F6: Beta = “how jumpy” the stock is
B7: Weighted Average Cost of Capital
B9: All Figures are in INR unless Stated otherwise
B11: Peer Comps
J12: Debt/ | K12: Debt/ | L12: Levered/ | M12: Unlevered/
B13: Name of the Comp | F13: Country | G13: Total Debt | H13: Total Equity | I13: Tax Rate 1 | J13: Equity | K13: Capital | L13: Beta 2 | M13: Beta 3
B15: Eternal Ltd | F15: India | G15: ='Retailing Companies'!E4 -> 2045 | H15: ='Retailing Companies'!D4 -> 316965.77 | I15: 0.3 | J15: =G15/H15 -> 0.0064518008 | K15: =G15/(G15+H15) -> 0.0064104419 | L15: 1.57 | M15: =L15/(1+(1-I15)*J15) -> 1.5629413 | N15: LB/(1+(1 - Tax)* Debt/Equity)
B16: Avenue Super. | F16: India | G16: ='Retailing Companies'!E5 -> 819.62 | H16: ='Retailing Companies'!D5 -> 287519.9 | I16: 0.3 | J16: =G16/H16 -> 0.0028506549 | K16: =G16/(G16+H16) -> 0.0028425517 | L16: 1.23 | M16: =L16/(1+(1-I16)*J16) -> 1.2275505
B17: Trent | F17: India | G17: ='Retailing Companies'!E6 -> 2237.19 | H17: ='Retailing Companies'!D6 -> 171192.1 | I17: 0.3 | J17: =G17/H17 -> 0.013068302 | K17: =G17/(G17+H17) -> 0.012899724 | L17: 1.38 | M17: =L17/(1+(1-I17)*J17) -> 1.3674905
B18: Swiggy | F18: India | G18: ='Retailing Companies'!E7 -> 1702.95 | H18: ='Retailing Companies'!D7 -> 103199.58 | I18: 0.3 | J18: =G18/H18 -> 0.016501521 | K18: =G18/(G18+H18) -> 0.016233641 | L18: 1.61 | M18: =L18/(1+(1-I18)*J18) -> 1.5916152
B19: Info Edg.(India) | F19: India | G19: ='Retailing Companies'!E8 -> 267.34 | H19: ='Retailing Companies'!D8 -> 86492.82 | I19: 0.3 | J19: =G19/H19 -> 0.0030908924 | K19: =G19/(G19+H19) -> 0.0030813682 | L19: 1.62 | M19: =L19/(1+(1-I19)*J19) -> 1.6165025
H21: Average | I21: =AVERAGE(I15:I19) -> 0.3 | J21: =AVERAGE(J15:J19) -> 0.0083926341 | K21: =AVERAGE(K15:K19) -> 0.0082935454 | L21: =AVERAGE(L15:L19) -> 1.482 | M21: =AVERAGE(M15:M19) -> 1.47322
H22: Median | I22: =MEDIAN(I15:I19) -> 0.3 | J22: =MEDIAN(J15:J19) -> 0.0064518008 | K22: =MEDIAN(K15:K19) -> 0.0064104419 | L22: =MEDIAN(L15:L19) -> 1.57 | M22: =MEDIAN(M15:M19) -> 1.5629413
B25: Cost of Debt | I25: Cost of Equity
B26: Pre-Tax Cost of Debt | G26: =83/819 -> 0.1013431 | I26: Risk Free Rate | M26: 0.06514
B27: Tax Rate | G27: 0.3 | I27: Equity Risk Premium | M27: ='Market Return'!G6-WACC!M26 -> 0.102008
B28: After-Tax Cost of Debt | G28: =G26* (1 - G27) -> 0.070940171 | I28: Levered Beta 4 | M28: =M37 -> 1.4798734
I29: Cost of Equity | M29: =M26+M27*M28 -> 0.21609893
B32: Capital Structure | I32: Levered Beta
D34: Current | E34: Target | I34: Comps Median Unlevered Beta | M34: =M21 -> 1.47322
B35: Total Debt | C35: =G16 -> 819.62 | D35: =C35/$C$37 -> 0.0028425517 | E35: =K22 -> 0.0064104419 | I35: Target Debt/Equity | M35: =E39 -> 0.0064518008
B36: Market Capitalization | C36: =H16 -> 287519.9 | D36: =C36/$C$37 -> 0.99715745 | E36: =E37-E35 -> 0.99358956 | I36: Tax Rate | M36: =G27 -> 0.3
B37: Total Capital | C37: =SUM(C35:C36) -> 288339.52 | D37: =C37/$C$37 -> 1 | E37: 1 | I37: Levered Beta | M37: =M34 * (1 + (1 - M36) * M35) -> 1.4798734
B39: Debt/Equity | D39: =D35/D36 -> 0.0028506549 | E39: =E35/E36 -> 0.0064518008
I40: Weighted Average Cost of Capital
I42: Total Equity | M42: =M29 -> 0.21609893
I43: Equity Weight | M43: =E36 -> 0.99358956
I45: Total Debt | M45: =G28 -> 0.070940171
I46: Debt Weight | M46: =E35 -> 0.0064104419
I48: WACC | M48: =(M42*M43)+(M45*M46) -> 0.2151684

Sheet Beta
B2: Avenue SuperMart!
D3: Beta formula = how much stock and market move together (covariance), divided by how volatile the market is (variance). Website Used - Investor.Com, PrimeInvestor.com, Screener | T3: Hindustan | AJ3: Eternal
C7: Beta Calculation - Regression
C9: Avenue SuperMart Data
AL10: Date | AM10: Closing Price | AN10: Return | AP10: Market
C11: Date | D11: Closing Price | E11: Return | G11: Closing Price | H11: Return | J11: Beta Drifting | O11: Beta 1 | P11: =SLOPE(E13:E116,H13:H116) -> 1.2295363 | V11: Date | W11: Closing Price | X11: Return | Z11: Closing Price | AA11: Return | AD11: Beta Rifting | AG11: Beta Calculation | AL11: 44402 | AM11: 133.5 | AR11: Beta 1 | AS11: =_xlfn.COVARIANCE.S(AN12:AN93,AP12:AP93)/_xlfn.VAR.S(AP12:AP93) -> 1.5670688 | AU11: Beta | AW11: =AT37 -> 1.5670688
C12: 44248 | D12: 2994.2 | G12: 14529.15 | J12: Raw Levered Beta | K12: =P11 -> 1.2295363 | O12: Beta 2 | P12: =_xlfn.COVARIANCE.S(E12:E116,H12:H116)/_xlfn.VAR.S(H12:H116) -> 1.2295363 | V12: 44248 | W12: 2123.59 | Z12: 14529.15 | AD12: Raw Leverred Beta | AE12: =AH14 -> 0.65936329 | AG12: Beta 1 | AH12: =SLOPE(X13:X116,AA13:AA116) -> 0.65936329 | AL12: 44409 | AM12: 131.35 | AN12: -0.0161 | AP12: 0.0301
C13: 44255 | D13: 3286.1 | E13: 0.0975 | G13: 14938.1 | H13: 0.0281 | J13: Beta Weight | K13: 0.75 | V13: 44255 | W13: 2192.37 | X13: 0.0324 | Z13: 14938.1 | AA13: 0.0281 | AD13: Beta Weight | AE13: 0.25 | AG13: Beta 2 | AH13: =_xlfn.COVARIANCE.S(X13:X116,AA13:AA116)/_xlfn.VAR.S(AA13:AA116) -> 0.65936329 | AL13: 44416 | AM13: 137.35 | AN13: 0.0457 | AP13: 0.0179
C14: 44262 | D14: 3129.35 | E14: -0.0477 | G14: 15030.95 | H14: 0.0062 | O14: Beta 3 | P14: =K93 -> 1.2295363 | V14: 44262 | W14: 2196.01 | X14: 0.0017 | Z14: 15030.95 | AA14: 0.0062 | AG14: Beta 3 | AH14: =AD42 -> 0.65936329 | AL14: 44423 | AM14: 139.3 | AN14: 0.0142 | AP14: -0.0048 | AR14: Beta | AS14: =SLOPE(AN12:AN93,AP12:AP93) -> 1.5670688
C15: 44269 | D15: 2960.3 | E15: -0.054 | G15: 14744 | H15: -0.0191 | J15: Market Beta | K15: 1 | V15: 44269 | W15: 2302.88 | X15: 0.0487 | Z15: 14744 | AA15: -0.0191 | AD15: Market Beta | AE15: 1 | AL15: 44430 | AM15: 124.7 | AN15: -0.1048 | AP15: 0.0155
C16: 44276 | D16: 2855.2 | E16: -0.0355 | G16: 14507.3 | H16: -0.0161 | J16: Market Weight Beta | K16: 0.25 | V16: 44276 | W16: 2308.71 | X16: 0.0025 | Z16: 14507.3 | AA16: -0.0161 | AD16: Market Weight | AE16: 0.75 | AL16: 44437 | AM16: 149.75 | AN16: 0.2009 | AP16: 0.037
C17: 44283 | D17: 2912.7 | E17: 0.0201 | G17: 14867.35 | H17: 0.0248 | V17: 44283 | W17: 2389.58 | X17: 0.035 | Z17: 14867.35 | AA17: 0.0248 | AL17: 44444 | AM17: 141.6 | AN17: -0.0544 | AP17: 0.0026 | AR17: Beta | AS17: =_xlfn.COVARIANCE.S(AP12:AP93,AN12:AN93)/_xlfn.VAR.S(AP12:AP93) -> 1.5670688
C18: 44290 | D18: 2947.75 | E18: 0.012 | G18: 14834.85 | H18: -0.0022 | J18: Adjusted Beta | K18: =(K12*K13)+(K15*K16) -> 1.1721522 | V18: 44290 | W18: 2466.18 | X18: 0.0321 | Z18: 14834.85 | AA18: -0.0022 | AD18: Adjusted Beta | AE18: =(AE12*AE13)+(AE15*AE16) -> 0.91484082 | AL18: 44451 | AM18: 137.9 | AN18: -0.0261 | AP18: 0.0124
C19: 44297 | D19: 2919.9 | E19: -0.0094 | G19: 14617.85 | H19: -0.0146 | V19: 44297 | W19: 2449.15 | X19: -0.0069 | Z19: 14617.85 | AA19: -0.0146 | AL19: 44458 | AM19: 136.65 | AN19: -0.0091 | AP19: 0.0152
C20: 44304 | D20: 2713.7 | E20: -0.0706 | G20: 14341.35 | H20: -0.0189 | V20: 44304 | W20: 2298.6 | X20: -0.0615 | Z20: 14341.35 | AA20: -0.0189 | AL20: 44465 | AM20: 138 | AN20: 0.0099 | AP20: -0.018 | AS20: SUMMARY OUTPUT
C21: 44311 | D21: 2852.9 | E21: 0.0513 | G21: 14631.1 | H21: 0.0202 | V21: 44311 | W21: 2344.42 | X21: 0.0199 | Z21: 14631.1 | AA21: 0.0202 | AL21: 44472 | AM21: 136.15 | AN21: -0.0134 | AP21: 0.0207
C22: 44318 | D22: 2895.5 | E22: 0.0149 | G22: 14823.15 | H22: 0.0131 | V22: 44318 | W22: 2401.64 | X22: 0.0244 | Z22: 14823.15 | AA22: 0.0131 | AL22: 44479 | AM22: 135 | AN22: -0.0084 | AP22: 0.0248 | AS22: Regression Statistics
C23: 44325 | D23: 2844.65 | E23: -0.0176 | G23: 14677.8 | H23: -0.0098 | V23: 44325 | W23: 2367.42 | X23: -0.0142 | Z23: 14677.8 | AA23: -0.0098 | AL23: 44486 | AM23: 137.75 | AN23: 0.0204 | AP23: -0.0122 | AS23: Multiple R | AT23: 0.429841
C24: 44332 | D24: 3034.15 | E24: 0.0666 | G24: 15175.3 | H24: 0.0339 | V24: 44332 | W24: 2352.88 | X24: -0.0061 | Z24: 15175.3 | AA24: 0.0339 | AL24: 44493 | AM24: 131.55 | AN24: -0.045 | AP24: -0.0245 | AS24: R Square | AT24: 0.18476328
C25: 44339 | D25: 3022.1 | E25: -0.004 | G25: 15435.65 | H25: 0.0172 | V25: 44339 | W25: 2312.49 | X25: -0.0172 | Z25: 15435.65 | AA25: 0.0172 | AC25: SUMMARY OUTPUT | AL25: 44500 | AM25: 131.35 | AN25: -0.0015 | AP25: 0.0139 | AS25: Adjusted R Square | AT25: 0.17457282
C26: 44346 | D26: 3197 | E26: 0.0579 | G26: 15670.25 | H26: 0.0152 | V26: 44346 | W26: 2332.76 | X26: 0.0088 | Z26: 15670.25 | AA26: 0.0152 | AL26: 44507 | AM26: 153 | AN26: 0.1648 | AP26: 0.0104 | AS26: Standard Error | AT26: 0.070983179
C27: 44353 | D27: 3175.55 | E27: -0.0067 | G27: 15799.35 | H27: 0.0082 | V27: 44353 | W27: 2357.11 | X27: 0.0104 | Z27: 15799.35 | AA27: 0.0082 | AC27: Regression Statistics | AL27: 44514 | AM27: 154.7 | AN27: 0.0111 | AP27: -0.0187 | AS27: Observations | AT27: 82
C28: 44360 | D28: 3317.7 | E28: 0.0448 | G28: 15683.35 | H28: -0.0073 | V28: 44360 | W28: 2473.05 | X28: 0.0492 | Z28: 15683.35 | AA28: -0.0073 | AC28: Multiple R | AD28: 0.40799237 | AL28: 44521 | AM28: 148.15 | AN28: -0.0423 | AP28: -0.0416
C29: 44367 | D29: 3315.35 | E29: -0.0007 | G29: 15860.35 | H29: 0.0113 | V29: 44367 | W29: 2438.94 | X29: -0.0138 | Z29: 15860.35 | AA29: 0.0113 | AC29: R Square | AD29: 0.16645777 | AL29: 44528 | AM29: 144.9 | AN29: -0.0219 | AP29: 0.01 | AS29: ANOVA
C30: 44374 | D30: 3314.3 | E30: -0.0003 | G30: 15722.2 | H30: -0.0087 | V30: 44374 | W30: 2477.44 | X30: 0.0158 | Z30: 15722.2 | AA30: -0.0087 | AC30: Adjusted R Square | AD30: 0.15828579 | AL30: 44535 | AM30: 140.55 | AN30: -0.03 | AP30: 0.0183 | AT30: df | AU30: SS | AV30: MS | AW30: F | AX30: Significance F
C31: 44381 | D31: 3377.6 | E31: 0.0191 | G31: 15689.8 | H31: -0.0021 | V31: 44381 | W31: 2441.73 | X31: -0.0144 | Z31: 15689.8 | AA31: -0.0021 | AC31: Standard Error | AD31: 0.030143772 | AL31: 44542 | AM31: 135.35 | AN31: -0.037 | AP31: -0.03 | AS31: Regression | AT31: 1 | AU31: 0.091355103 | AV31: 0.091355103 | AW31: 18.131007 | AX31: 5.5742683e-05
C32: 44388 | D32: 3349.2 | E32: -0.0084 | G32: 15923.4 | H32: 0.0149 | V32: 44388 | W32: 2407.81 | X32: -0.0139 | Z32: 15923.4 | AA32: 0.0149 | AC32: Observations | AD32: 104 | AL32: 44549 | AM32: 131.45 | AN32: -0.0288 | AP32: 0.0011 | AS32: Residual | AT32: 80 | AU32: 0.40308893 | AV32: 0.0050386117
C33: 44395 | D33: 3413.2 | E33: 0.0191 | G33: 15856.05 | H33: -0.0042 | V33: 44395 | W33: 2348.75 | X33: -0.0245 | Z33: 15856.05 | AA33: -0.0042 | AL33: 44556 | AM33: 137.4 | AN33: 0.0453 | AP33: 0.0206 | AS33: Total | AT33: 81 | AU33: 0.49444404
C34: 44402 | D34: 3500.8 | E34: 0.0257 | G34: 15763.05 | H34: -0.0059 | V34: 44402 | W34: 2324.05 | X34: -0.0105 | Z34: 15763.05 | AA34: -0.0059 | AC34: ANOVA | AL34: 44563 | AM34: 129.25 | AN34: -0.0593 | AP34: 0.0264
C35: 44409 | D35: 3529.2 | E35: 0.0081 | G35: 16238.2 | H35: 0.0301 | V35: 44409 | W35: 2362.09 | X35: 0.0164 | Z35: 16238.2 | AA35: 0.0301 | AD35: df | AE35: SS | AF35: MS | AG35: F | AH35: Significance F | AL35: 44570 | AM35: 133.6 | AN35: 0.0337 | AP35: 0.0249 | AT35: Coefficients | AU35: Standard Error | AV35: t Stat | AW35: P-value | AX35: Lower 95% | AY35: Upper 95% | AZ35: Lower 95.0% | BA35: Upper 95.0%
C36: 44416 | D36: 3594.55 | E36: 0.0185 | G36: 16529.1 | H36: 0.0179 | V36: 44416 | W36: 2394.96 | X36: 0.0139 | Z36: 16529.1 | AA36: 0.0179 | AC36: Regression | AD36: 1 | AE36: 0.018508526 | AF36: 0.018508526 | AG36: 20.369325 | AH36: 1.7153431e-05 | AL36: 44577 | AM36: 113.65 | AN36: -0.1493 | AP36: -0.035 | AS36: Intercept | AT36: -0.010142178 | AU36: 0.0078575385 | AV36: -1.2907577 | AW36: 0.20050552 | AX36: -0.025779178 | AY36: 0.0054948217 | AZ36: -0.025779178 | BA36: 0.0054948217
C37: 44423 | D37: 3643.1 | E37: 0.0135 | G37: 16450.5 | H37: -0.0048 | V37: 44423 | W37: 2609.01 | X37: 0.0894 | Z37: 16450.5 | AA37: -0.0048 | AC37: Residual | AD37: 102 | AE37: 0.092681992 | AF37: 0.00090864698 | AL37: 44584 | AM37: 89.55 | AN37: -0.2121 | AP37: -0.0292 | AS37: X Variable 1 | AT37: 1.5670688 | AU37: 0.36802482 | AV37: 4.258052 | AW37: 5.5742683e-05 | AX37: 0.83467609 | AY37: 2.2994616 | AZ37: 0.83467609 | BA37: 2.2994616
C38: 44430 | D38: 3833.05 | E38: 0.0521 | G38: 16705.2 | H38: 0.0155 | V38: 44430 | W38: 2667.33 | X38: 0.0224 | Z38: 16705.2 | AA38: 0.0155 | AC38: Total | AD38: 103 | AE38: 0.11119052 | AL38: 44591 | AM38: 94.2 | AN38: 0.0519 | AP38: 0.0242
C39: 44437 | D39: 3938.9 | E39: 0.0276 | G39: 17323.6 | H39: 0.037 | V39: 44437 | W39: 2755.73 | X39: 0.0331 | Z39: 17323.6 | AA39: 0.037 | AL39: 44598 | AM39: 88.7 | AN39: -0.0584 | AP39: -0.0081
C40: 44444 | D40: 3950.5 | E40: 0.0029 | G40: 17369.25 | H40: 0.0026 | V40: 44444 | W40: 2799.5 | X40: 0.0159 | Z40: 17369.25 | AA40: 0.0026 | AD40: Coefficients | AE40: Standard Error | AF40: t Stat | AG40: P-value | AH40: Lower 95% | AL40: 44605 | AM40: 85.9 | AN40: -0.0316 | AP40: -0.0057
C41: 44451 | D41: 4239.65 | E41: 0.0732 | G41: 17585.15 | H41: 0.0124 | V41: 44451 | W41: 2711.45 | X41: -0.0315 | Z41: 17585.15 | AA41: 0.0124 | AC41: Intercept | AD41: 0.00070350567 | AE41: 0.0029698487 | AF41: 0.23688266 | AG41: 0.81322291 | AH41: -0.0051871752 | AL41: 44612 | AM41: 78.8 | AN41: -0.0827 | AP41: -0.0358
C42: 44458 | D42: 4422.35 | E42: 0.0431 | G42: 17853.2 | H42: 0.0152 | V42: 44458 | W42: 2735.76 | X42: 0.009 | Z42: 17853.2 | AA42: 0.0152 | AC42: X Variable 1 | AD42: 0.65936329 | AE42: 0.14609537 | AF42: 4.5132389 | AG42: 1.7153431e-05 | AH42: 0.36958382 | AL42: 44619 | AM42: 80.2 | AN42: 0.0178 | AP42: -0.0248
C43: 44465 | D43: 4235.6 | E43: -0.0422 | G43: 17532.05 | H43: -0.018 | V43: 44465 | W43: 2693.33 | X43: -0.0155 | Z43: 17532.05 | AA43: -0.018 | AL43: 44626 | AM43: 79.9 | AN43: -0.0037 | AP43: 0.0237
C44: 44472 | D44: 4407.95 | E44: 0.0407 | G44: 17895.2 | H44: 0.0207 | V44: 44472 | W44: 2629.58 | X44: -0.0237 | Z44: 17895.2 | AA44: 0.0207 | AL44: 44633 | AM44: 80.85 | AN44: 0.0119 | AP44: 0.0395
C45: 44479 | D45: 5323.75 | E45: 0.2078 | G45: 18338.55 | H45: 0.0248 | V45: 44479 | W45: 2639.04 | X45: 0.0036 | Z45: 18338.55 | AA45: 0.0248 | AL45: 44640 | AM45: 80.6 | AN45: -0.0031 | AP45: -0.0078
...

Sheet Intrinsic Growth
B3: ="Intrinsic Growth - "&UPDATE -> Intrinsic Growth - Tata Motors
B4: Calculation of ROIC | C4: ='Asian Paints Data'!C2 -> 41699 | D4: ='Asian Paints Data'!D2 -> 42064 | E4: ='Asian Paints Data'!E2 -> 42430 | F4: ='Asian Paints Data'!F2 -> 42795 | G4: ='Asian Paints Data'!G2 -> 43160 | H4: ='Asian Paints Data'!H2 -> 43525 | I4: ='Asian Paints Data'!I2 -> 43891 | J4: ='Asian Paints Data'!J2 -> 44256 | ... N4: ='Asian Paints Data'!N2 -> 45717
B6: Current Assets
B7: Inventories | C7: ='Asian Paints Data'!C37 -> 2070 | D7: ='Asian Paints Data'!D37 -> 2259 | E7: ='Asian Paints Data'!E37 -> 1998 | F7: ='Asian Paints Data'!F37 -> 2627 | G7: ='Asian Paints Data'!G37 -> 2658 | H7: ='Asian Paints Data'!H37 -> 3150 | I7: ='Asian Paints Data'!I37 -> 3390 | J7: ='Asian Paints Data'!J37 -> 3799 | ... N7: ='Asian Paints Data'!N37 -> 6719
B8: Trade Receivables | C8: ='Asian Paints Data'!C38 -> 1110 | D8: ='Asian Paints Data'!D38 -> 1182 | E8: ='Asian Paints Data'!E38 -> 1187 | F8: ='Asian Paints Data'!F38 -> 1447 | G8: ='Asian Paints Data'!G38 -> 1731 | H8: ='Asian Paints Data'!H38 -> 1907 | I8: ='Asian Paints Data'!I38 -> 1795 | J8: ='Asian Paints Data'!J38 -> 2602 | ... N8: ='Asian Paints Data'!N38 -> 4314
B9: Loans and Advances | C9: ='Asian Paints Data'!C43 -> 7 | D9: ='Asian Paints Data'!D43 -> 8 | E9: ='Asian Paints Data'!E43 -> 9 | F9: ='Asian Paints Data'!F43 -> 14 | G9: ='Asian Paints Data'!G43 -> 13 | H9: ='Asian Paints Data'!H43 -> 16 | I9: ='Asian Paints Data'!I43 -> 12 | J9: ='Asian Paints Data'!J43 -> 11 | ... N9: ='Asian Paints Data'!N43 -> 22
B10: Other Asset Items | C10: ='Asian Paints Data'!C44 -> 603 | D10: ='Asian Paints Data'!D44 -> 817 | E10: ='Asian Paints Data'!E44 -> 705 | F10: ='Asian Paints Data'!F44 -> 1303 | G10: ='Asian Paints Data'!G44 -> 1678 | H10: ='Asian Paints Data'!H44 -> 1456 | I10: ='Asian Paints Data'!I44 -> 1727 | J10: ='Asian Paints Data'!J44 -> 2555 | ... N10: ='Asian Paints Data'!N44 -> 3319
B11: Total Current Assets | C11: =SUM(C7:C10) -> 3790 | D11: =SUM(D7:D10) -> 4266 | E11: =SUM(E7:E10) -> 3899 | F11: =SUM(F7:F10) -> 5391 | G11: =SUM(G7:G10) -> 6080 | H11: =SUM(H7:H10) -> 6529 | I11: =SUM(I7:I10) -> 6924 | J11: =SUM(J7:J10) -> 8967 | ... N11: =SUM(N7:N10) -> 14374
B13: Current Liabilites
B14: ='Asian Paints Data'!B13 -> Trade Payables | C14: ='Asian Paints Data'!C13 -> 1746 | D14: ='Asian Paints Data'!D13 -> 1549 | E14: ='Asian Paints Data'!E13 -> 1565 | F14: ='Asian Paints Data'!F13 -> 1923 | G14: ='Asian Paints Data'!G13 -> 2160 | H14: ='Asian Paints Data'!H13 -> 2394 | I14: ='Asian Paints Data'!I13 -> 2137 | ... N14: ='Asian Paints Data'!N13 -> 3848
B15: ='Asian Paints Data'!B14 -> Advance from Customers | C15: ='Asian Paints Data'!C14 -> 0 | D15: ='Asian Paints Data'!D14 -> 5 | E15: ='Asian Paints Data'!E14 -> 12 | F15: ='Asian Paints Data'!F14 -> 17 | G15: ='Asian Paints Data'!G14 -> 16 | H15: ='Asian Paints Data'!H14 -> 13 | I15: ='Asian Paints Data'!I14 -> 29 | ... N15: ='Asian Paints Data'!N14 -> 173
B16: ='Asian Paints Data'!B15 -> Other liability items | C16: ='Asian Paints Data'!C15 -> 1795 | D16: ='Asian Paints Data'!D15 -> 1937 | E16: ='Asian Paints Data'!E15 -> 1750 | F16: ='Asian Paints Data'!F15 -> 1925 | G16: ='Asian Paints Data'!G15 -> 2316 | H16: ='Asian Paints Data'!H15 -> 2690 | I16: ='Asian Paints Data'!I15 -> 2320 | ... N16: ='Asian Paints Data'!N15 -> 3985
B17: Total Current Liabilites | C17: =SUM(C14:C16) -> 3541 | D17: =SUM(D14:D16) -> 3491 | E17: =SUM(E14:E16) -> 3327 | F17: =SUM(F14:F16) -> 3865 | G17: =SUM(G14:G16) -> 4492 | H17: =SUM(H14:H16) -> 5097 | I17: =SUM(I14:I16) -> 4486 | J17: =SUM(J14:J16) -> 6033 | ... N17: =SUM(N14:N16) -> 8006
B19: Net Working Capital | C19: =C11-C17 -> 249 | D19: =D11-D17 -> 775 | E19: =E11-E17 -> 572 | F19: =F11-F17 -> 1526 | G19: =G11-G17 -> 1588 | H19: =H11-H17 -> 1432 | I19: =I11-I17 -> 2438 | J19: =J11-J17 -> 2934 | ... N19: =N11-N17 -> 6368
B21: Fixed Assets
B22: ='Asian Paints Data'!B20 -> Land | C22: ='Asian Paints Data'!C20 -> 247 | D22: ='Asian Paints Data'!D20 -> 251 | E22: ='Asian Paints Data'!E20 -> 429 | F22: ='Asian Paints Data'!F20 -> 408 | G22: ='Asian Paints Data'!G20 -> 586 | H22: ='Asian Paints Data'!H20 -> 605 | I22: ='Asian Paints Data'!I20 -> 640 | ... N22: ='Asian Paints Data'!N20 -> 1050
B23: ='Asian Paints Data'!B21 -> Building | C23: ='Asian Paints Data'!C21 -> 931 | D23: ='Asian Paints Data'!D21 -> 962 | E23: ='Asian Paints Data'!E21 -> 923 | F23: ='Asian Paints Data'!F21 -> 931 | G23: ='Asian Paints Data'!G21 -> 957 | H23: ='Asian Paints Data'!H21 -> 2402 | I23: ='Asian Paints Data'!I21 -> 2257 | ... N23: ='Asian Paints Data'!N21 -> 4136
B24: ='Asian Paints Data'!B22 -> Plant Machinery | C24: ='Asian Paints Data'!C22 -> 2054 | D24: ='Asian Paints Data'!D22 -> 2132 | E24: ='Asian Paints Data'!E22 -> 1793 | F24: ='Asian Paints Data'!F22 -> 1980 | G24: ='Asian Paints Data'!G22 -> 2157 | H24: ='Asian Paints Data'!H22 -> 4006 | I24: ='Asian Paints Data'!I22 -> 4208 | ... N24: ='Asian Paints Data'!N22 -> 7576
B25: ='Asian Paints Data'!B23 -> Equipments | C25: ='Asian Paints Data'!C23 -> 155 | D25: ='Asian Paints Data'!D23 -> 171 | E25: ='Asian Paints Data'!E23 -> 97 | F25: ='Asian Paints Data'!F23 -> 119 | G25: ='Asian Paints Data'!G23 -> 200 | H25: ='Asian Paints Data'!H23 -> 221 | I25: ='Asian Paints Data'!I23 -> 241 | ... N25: ='Asian Paints Data'!N23 -> 325
B26: ='Asian Paints Data'!B24 -> Furniture n fittings | C26: ='Asian Paints Data'!C24 -> 71 | D26: ='Asian Paints Data'!D24 -> 83 | E26: ='Asian Paints Data'!E24 -> 49 | F26: ='Asian Paints Data'!F24 -> 59 | G26: ='Asian Paints Data'!G24 -> 72 | H26: ='Asian Paints Data'!H24 -> 88 | I26: ='Asian Paints Data'!I24 -> 94 | ... N26: ='Asian Paints Data'!N24 -> 203
